Workbook

Sheet cleaned data 
A1: order_id | B1: date | C1: product | D1: quantity | E1: unit_price | F1: total | G1: region | H1: salesperson | J1: salesperson
A2: SO-1001 | B2: 46146 | C2: Mechanical Keyboard | D2: 6 | E2: 112.7 | F2: 676.2 | G2: North | H2: =SUBSTITUTE(J2,"TomÃ¡s Tanaka","Tomas Tanaka") -> Sofia Kowalski | J2: Sofia Kowalski
A3: SO-1002 | B3: 46199 | C3: USB-C Hub | D3: 6 | E3: 35.78 | F3: 214.68 | G3: South | H3: =SUBSTITUTE(J3,"TomÃ¡s Tanaka","Tomas Tanaka") -> Sofia Kowalski | J3: Sofia Kowalski
A4: SO-1003 | B4: 46089 | C4: Standing Desk | D4: 1 | E4: 111.15 | F4: 111.15 | G4: South | H4: =SUBSTITUTE(J4,"TomÃ¡s Tanaka","Tomas Tanaka") -> Elena Cohen | J4: Elena Cohen
A5: SO-1004 | B5: 46067 | C5: Webcam 1080p | D5: 1 | E5: 112.67 | F5: 112.67 | G5: East | H5: =SUBSTITUTE(J5,"TomÃ¡s Tanaka","Tomas Tanaka") -> Omar Haddad | J5: Omar Haddad
A6: SO-1005 | B6: 46075 | C6: Webcam 1080p | D6: 1 | E6: 54.09 | F6: 54.09 | G6: Central | H6: =SUBSTITUTE(J6,"TomÃ¡s Tanaka","Tomas Tanaka") -> Sofia Kowalski | J6: Sofia Kowalski
A7: SO-1006 | B7: 46040 | C7: Desk Lamp | D7: 4 | E7: 215.54 | F7: 862.16 | G7: West | H7: =SUBSTITUTE(J7,"TomÃ¡s Tanaka","Tomas Tanaka") -> Omar Haddad | J7: Omar Haddad
A8: SO-1007 | B8: 46125 | C8: Cable Organizer | D8: 3 | E8: 17.52 | F8: 52.56 | G8: East | H8: =SUBSTITUTE(J8,"TomÃ¡s Tanaka","Tomas Tanaka") -> Tomas Tanaka | J8: Tomas Tanaka
A9: SO-1008 | B9: 46148 | C9: Noise-Cancelling Headphones | D9: 6 | E9: 181.65 | F9: 1089.9 | G9: West | H9: =SUBSTITUTE(J9,"TomÃ¡s Tanaka","Tomas Tanaka") -> Omar Haddad | J9: Omar Haddad
A10: SO-1009 | B10: 46116 | C10: Laptop Stand | D10: 8 | E10: 28.72 | F10: 229.76 | G10: East | H10: =SUBSTITUTE(J10,"TomÃ¡s Tanaka","Tomas Tanaka") -> Sofia Kowalski | J10: Sofia Kowalski
A11: SO-1010 | B11: 46082 | C11: Ergonomic Chair | D11: 7 | E11: 143.97 | F11: 1007.79 | G11: East | H11: =SUBSTITUTE(J11,"TomÃ¡s Tanaka","Tomas Tanaka") -> Priya Herrera | J11: Priya Herrera
A12: SO-1011 | B12: 46049 | C12: Cable Organizer | D12: 7 | E12: 147.79 | F12: 1034.53 | G12: North | H12: =SUBSTITUTE(J12,"TomÃ¡s Tanaka","Tomas Tanaka") -> Priya Herrera | J12: Priya Herrera
A13: SO-1012 | B13: 46161 | C13: Wireless Mouse | D13: 5 | E13: 206.67 | F13: 1033.35 | G13: North | H13: =SUBSTITUTE(J13,"TomÃ¡s Tanaka","Tomas Tanaka") -> Chen Bennett | J13: Chen Bennett
... A71: SO-1070 | B71: 46147 | C71: Laptop Stand | D71: 8 | E71: 114.94 | F71: 919.52 | G71: West | H71: =SUBSTITUTE(J71,"TomÃ¡s Tanaka","Tomas Tanaka") -> Tomas Tanaka | J71: TomÃ¡s Tanaka
A72: SO-1071 | B72: 46043 | C72: External SSD 1TB | D72: 7 | E72: 123.53 | F72: 864.71 | G72: East | H72: =SUBSTITUTE(J72,"TomÃ¡s Tanaka","Tomas Tanaka") -> Priya Herrera | J72: Priya Herrera | K72: =SUBSTITUTE(I72,"TomÃ¡s Tanaka","Tomas Tanaka")
A73: SO-1072 | B73: 46133 | C73: Mechanical Keyboard | D73: 6 | E73: 106.03 | F73: 636.18 | G73: North | H73: =SUBSTITUTE(J73,"TomÃ¡s Tanaka","Tomas Tanaka") -> Tomas Tanaka | J73: TomÃ¡s Tanaka | K73: =SUBSTITUTE(I73,"TomÃ¡s Tanaka","Tomas Tanaka")
A74: SO-1073 | B74: 46069 | C74: Wireless Mouse | D74: 8 | E74: 179.22 | F74: 1433.76 | G74: Central | H74: =SUBSTITUTE(J74,"TomÃ¡s Tanaka","Tomas Tanaka") -> Tomas Tanaka | J74: TomÃ¡s Tanaka | K74: =SUBSTITUTE(I74,"TomÃ¡s Tanaka","Tomas Tanaka")
A75: SO-1074 | B75: 46133 | C75: Laptop Stand | D75: 7 | E75: 162.66 | F75: 1138.62 | G75: North | H75: =SUBSTITUTE(J75,"TomÃ¡s Tanaka","Tomas Tanaka") -> Chen Bennett | J75: Chen Bennett | K75: =SUBSTITUTE(I75,"TomÃ¡s Tanaka","Tomas Tanaka")
A76: SO-1075 | B76: 46144 | C76: Ergonomic Chair | D76: 5 | E76: 207.98 | F76: 1039.9 | G76: West | H76: =SUBSTITUTE(J76,"TomÃ¡s Tanaka","Tomas Tanaka") -> Sofia Kowalski | J76: Sofia Kowalski | K76: =SUBSTITUTE(I76,"TomÃ¡s Tanaka","Tomas Tanaka")
A77: SO-1076 | B77: 46160 | C77: 27-inch Monitor | D77: 7 | E77: 123.91 | F77: 867.37 | G77: North | H77: =SUBSTITUTE(J77,"TomÃ¡s Tanaka","Tomas Tanaka") -> Sofia Kowalski | J77: Sofia Kowalski | K77: =SUBSTITUTE(I77,"TomÃ¡s Tanaka","Tomas Tanaka")
A78: SO-1077 | B78: 46158 | C78: Webcam 1080p | D78: 4 | E78: 134.83 | F78: 539.32 | G78: Central | H78: =SUBSTITUTE(J78,"TomÃ¡s Tanaka","Tomas Tanaka") -> Tomas Tanaka | J78: TomÃ¡s Tanaka | K78: =SUBSTITUTE(I78,"TomÃ¡s Tanaka","Tomas Tanaka")
A79: SO-1078 | B79: 46163 | C79: Noise-Cancelling Headphones | D79: 6 | E79: 80.19 | F79: 481.14 | G79: North | H79: =SUBSTITUTE(J79,"TomÃ¡s Tanaka","Tomas Tanaka") -> Omar Haddad | J79: Omar Haddad | K79: =SUBSTITUTE(I79,"TomÃ¡s Tanaka","Tomas Tanaka")
A80: SO-1079 | B80: 46116 | C80: Standing Desk | D80: 6 | E80: 45.83 | F80: 274.98 | G80: North | H80: =SUBSTITUTE(J80,"TomÃ¡s Tanaka","Tomas Tanaka") -> Omar Haddad | J80: Omar Haddad | K80: =SUBSTITUTE(I80,"TomÃ¡s Tanaka","Tomas Tanaka")
A81: SO-1080 | B81: 46093 | C81: Cable Organizer | D81: 7 | E81: 97.22 | F81: 680.54 | G81: West | H81: =SUBSTITUTE(J81,"TomÃ¡s Tanaka","Tomas Tanaka") -> Chen Bennett | J81: Chen Bennett | K81: =SUBSTITUTE(I81,"TomÃ¡s Tanaka","Tomas Tanaka")
A82: SO-1081 | B82: 46100 | C82: Ergonomic Chair | D82: 7 | E82: 145.34 | F82: 1017.38 | G82: South | H82: =SUBSTITUTE(J82,"TomÃ¡s Tanaka","Tomas Tanaka") -> Chen Bennett | J82: Chen Bennett | K82: =SUBSTITUTE(I82,"TomÃ¡s Tanaka","Tomas Tanaka")
A83: SO-1082 | B83: 46045 | C83: USB-C Hub | D83: 1 | E83: 78.43 | F83: 78.43 | G83: East | H83: =SUBSTITUTE(J83,"TomÃ¡s Tanaka","Tomas Tanaka") -> Elena Cohen | J83: Elena Cohen | K83: =SUBSTITUTE(I83,"TomÃ¡s Tanaka","Tomas Tanaka")
... A241: SO-1240 | B241: 46116 | C241: Webcam 1080p | D241: 6 | E241: 160.47 | F241: 962.82 | G241: Central | H241: =SUBSTITUTE(J241,"TomÃ¡s Tanaka","Tomas Tanaka") -> Chen Bennett | J241: Chen Bennett | K241: =SUBSTITUTE(I241,"TomÃ¡s Tanaka","Tomas Tanaka")

Sheet raw data
A1: order_id | B1: date | C1: product | D1: quantity | E1: unit_price | F1: total | G1: region | H1: salesperson
A2: SO-1001 | B2: 46146 | C2: Mechanical Keyboard | D2: 6 | E2: 112.7 | F2: 676.2 | G2: North | H2: Sofia Kowalski
A3: SO-1002 | B3: 46199 | C3: USB-C Hub | D3: 6 | E3: 35.78 | F3: 214.68 | G3: South | H3: Sofia Kowalski
A4: SO-1003 | B4: 46089 | C4: Standing Desk | D4: 1 | E4: 111.15 | F4: 111.15 | G4: South | H4: Elena Cohen
A5: SO-1004 | B5: 46067 | C5: Webcam 1080p | D5: 1 | E5: 112.67 | F5: 112.67 | G5: East | H5: Omar Haddad
A6: SO-1005 | B6: 46075 | C6: Webcam 1080p | D6: 1 | E6: 54.09 | F6: 54.09 | G6: Central | H6: Sofia Kowalski
A7: SO-1006 | B7: 46040 | C7: Desk Lamp | D7: 4 | E7: 215.54 | F7: 862.16 | G7: West | H7: Omar Haddad
A8: SO-1007 | B8: 46125 | C8: Cable Organizer | D8: 3 | E8: 17.52 | F8: 52.56 | G8: East | H8: TomÃ¡s Tanaka
A9: SO-1008 | B9: 46148 | C9: Noise-Cancelling Headphones | D9: 6 | E9: 181.65 | F9: 1089.9 | G9: West | H9: Omar Haddad
A10: SO-1009 | B10: 46116 | C10: Laptop Stand | D10: 8 | E10: 28.72 | F10: 229.76 | G10: East | H10: Sofia Kowalski
A11: SO-1010 | B11: 46082 | C11: Ergonomic Chair | D11: 7 | E11: 143.97 | F11: 1007.79 | G11: East | H11: Priya Herrera
A12: SO-1011 | B12: 46049 | C12: Cable Organizer | D12: 7 | E12: 147.79 | F12: 1034.53 | G12: North | H12: Priya Herrera
A13: SO-1012 | B13: 46161 | C13: Wireless Mouse | D13: 5 | E13: 206.67 | F13: 1033.35 | G13: North | H13: Chen Bennett
... A241: SO-1240 | B241: 46116 | C241: Webcam 1080p | D241: 6 | E241: 160.47 | F241: 962.82 | G241: Central | H241: Chen Bennett

Sheet Sheet1
A1: ANALYSIS OF SALES DATASET
A5: {=_xlfn.SEQUENCE(12,1,1,1)} -> 1 | B5: duplicate records | D5: :NONE
A6: 2 | B6: missing Value | D6: :NONE
A7: 3 | B7: Duplicate Order IDs | D7: :NONE
A8: 4 | B8: Blank Order IDs | D8: :NONE
A9: 5 | B9: Blank Dates | D9: :NONE
A10: 6 | B10: Blank Products | D10: :NONE
A11: 7 | B11: Blank Quantity | D11: :NONE
A12: 8 | B12: Blank Unit Price | D12: :NONE
A13: 9 | B13: Blank Total | D13: :NONE
A14: 10 | B14: Blank Region | D14: :NONE
A15: 11 | B15: Blank Salesperson | D15: :NONE
A16: 12 | B16: Wrong Total | D16: :NONE
B18: Result
A20: {=_xlfn.SEQUENCE(4,1,1,1)} -> 1 | B20: total sales | E20: =SUM('cleaned data '!F2:F241) -> 142437.14
A21: 2 | B21: Total Quantity sold | E21: =SUM('cleaned data '!D2:D241) -> 1108
A22: 3 | B22: Average Order Value | E22: =AVERAGE('cleaned data '!F2:F241) -> 593.48808
A23: 4 | B23: Total sales of Each product :
B24: {=_xlfn.SEQUENCE(12,1,1,1)} -> 1 | C24: {=_xlfn.UNIQUE('cleaned data '!C2:C241)} -> Mechanical Keyboard | E24: =SUMIF('cleaned data '!C2:C241,C24,'cleaned data '!F2:F241) -> 9513.33
B25: 2 | C25: USB-C Hub | E25: =SUMIF('cleaned data '!C3:C242,C25,'cleaned data '!F3:F242) -> 8082.1
B26: 3 | C26: Standing Desk | E26: =SUMIF('cleaned data '!C4:C243,C26,'cleaned data '!F4:F243) -> 6526.55
B27: 4 | C27: Webcam 1080p | E27: =SUMIF('cleaned data '!C5:C244,C27,'cleaned data '!F5:F244) -> 16809.84
B28: 5 | C28: Desk Lamp | E28: =SUMIF('cleaned data '!C6:C245,C28,'cleaned data '!F6:F245) -> 10445.8
B29: 6 | C29: Cable Organizer | E29: =SUMIF('cleaned data '!C7:C246,C29,'cleaned data '!F7:F246) -> 16142.37
B30: 7 | C30: Noise-Cancelling Headphones | E30: =SUMIF('cleaned data '!C8:C247,C30,'cleaned data '!F8:F247) -> 10674.32
B31: 8 | C31: Laptop Stand | E31: =SUMIF('cleaned data '!C9:C248,C31,'cleaned data '!F9:F248) -> 18713.9
B32: 9 | C32: Ergonomic Chair | E32: =SUMIF('cleaned data '!C10:C249,C32,'cleaned data '!F10:F249) -> 10624.93
B33: 10 | C33: Wireless Mouse | E33: =SUMIF('cleaned data '!C11:C250,C33,'cleaned data '!F11:F250) -> 14290.77
B34: 11 | C34: External SSD 1TB | E34: =SUMIF('cleaned data '!C12:C251,C34,'cleaned data '!F12:F251) -> 12103.9
B35: 12 | C35: 27-inch Monitor | E35: =SUMIF('cleaned data '!C13:C252,C35,'cleaned data '!F13:F252) -> 8509.33
C37: Highest Sale Product | E37: laptop stand | F37: =MAX(E24:E35) -> 18713.9
C38: Lowest sale Product | E38: Standing Desk | F38: =MIN(E24:E35) -> 6526.55
A39: 5 | B39: Total Sales of Each Region
B40: {=_xlfn.SEQUENCE(5)} -> 1 | C40: {=_xlfn.UNIQUE('cleaned data '!G2:G241)} -> North | D40: =SUMIF('cleaned data '!G2:G241,C40,'cleaned data '!F2:F241) -> 28925
B41: 2 | C41: South | D41: =SUMIF('cleaned data '!G3:G242,C41,'cleaned data '!F3:F242) -> 30083.51
B42: 3 | C42: East | D42: =SUMIF('cleaned data '!G4:G243,C42,'cleaned data '!F4:F243) -> 26485.82
B43: 4 | C43: Central | D43: =SUMIF('cleaned data '!G5:G244,C43,'cleaned data '!F5:F244) -> 30787.94
B44: 5 | C44: West | D44: =SUMIF('cleaned data '!G6:G245,C44,'cleaned data '!F6:F245) -> 26154.87
A46: 6 | B46: Monthly Sales
B47: {=_xlfn.SEQUENCE(12,1,1,1)} -> 1 | C47: JANUARY | E47: {=SUMPRODUCT((MONTH('cleaned data '!B2:B241)=ROW()-46)*'cleaned data '!F2:F241)} -> 24177.45
...
